Workbook

Sheet Вторник 1
AG2: SOY3 | DS2: SOY2 | EM2: Для переноса данных с прошлого дня копируем таблицу в пределах границ Таблица сделана в штате 463 Союзом Carent Morte(CRT)
BB3: XS08 | BZ3: S06 | CZ3: XS22 | FG3: Союзы | FH3: Нефти по дняM недели заработали | FT3: ИТОГО | FY3: 2
FH4: Вторник 1 | FI4: Среда 2 | FJ4: Четверг 3 | FK4: Пятница 4 | FL4: Суббота 5 | FM4: Воскресенье 6 | FN4: Понедельник 7 | FO4: Вторник 8 | FP4: Среда 9 | FQ4: Четверг 10 | FR4: Пятница 11 | FS4: Суббота 12
BB5: FREE | BZ5: FREE | CZ5: FREE | FG5: SOY1 | FH5: =SUMIF($FI$17:$FI$181,FG5,$FJ$17:$FJ$181) -> 0 | FT5: =SUM(FH5:FS5) -> 0
FG6: SOY2 | FH6: =SUMIF($FI$17:$FI$181,FG6,$FJ$17:$FJ$181) -> 0 | FT6: =SUM(FH6:FS6) -> 0
FG7: SOY3 | FH7: =SUMIF($FI$17:$FI$181,FG7,$FJ$17:$FJ$181) -> 0 | FT7: =SUM(FH7:FS7) -> 0
FG8: SOY4 | FH8: =SUMIF($FI$17:$FI$181,FG8,$FJ$17:$FJ$181) -> 0 | FT8: =SUM(FH8:FS8) -> 0
BN9: XS14 | CL9: XS21 | FG9: SOY5 | FH9: =SUMIF($FI$17:$FI$181,FG9,$FJ$17:$FJ$181) -> 0 | FT9: =SUM(FH9:FS9) -> 0
Z10: XS02 | EA10: XS32 | FG10: SOY6 | FH10: =SUMIF($FI$17:$FI$181,FG10,$FJ$17:$FJ$181) -> 0 | FT10: =SUM(FH10:FS10) -> 0
BN11: FREE | BZ11: S08 | CL11: FREE | FG11: SOY7 | FH11: =SUMIF($FI$17:$FI$181,FG11,$FJ$17:$FJ$181) -> 0 | FT11: =SUM(FH11:FS11) -> 0
Z12: FREE | EA12: FREE | FG12: SOY8 | FH12: =SUMIF($FI$17:$FI$181,FG12,$FJ$17:$FJ$181) -> 0 | FT12: =SUM(FH12:FS12) -> 0
BZ13: FREE | DI13: XS26 | FG13: FREE
AS14: XS07
DI15: FREE | FG15: Точка добычи | FI15: Cоюз | FJ15: Дают очков
AS16: FREE
FG17: ЛОГОВА | FH17: XS01 | FI17: =K27 -> FREE | FJ17: 80
S18: S01 | AI18: XS06 | EH18: S18 | FH18: XS02 | FI18: =Z12 -> FREE | FJ18: 80
DS19: XS31 | FH19: XS03 | FI19: =C52 -> FREE | FJ19: 80
S20: FREE | AI20: FREE | BN20: XS16 | CM20: XS20 | EH20: FREE | FH20: XS04 | FI20: =O44 -> FREE | FJ20: 80
DB21: XS25 | DS21: FREE | FH21: XS05 | FI21: =S36 -> FREE | FJ21: 80
AZ22: XS12 | BN22: FREE | CM22: FREE | FH22: XS06 | FI22: =AI20 -> FREE | FJ22: 80
DB23: FREE | FH23: XS07 | FI23: =AS16 -> FREE | FJ23: 80
AZ24: FREE | FH24: XS08 | FI24: =BB5 -> FREE | FJ24: 80
K25: XS01 | AQ25: XS11 | DK25: XS30 | FH25: XS09 | FI25: =V51 -> FREE | FJ25: 80
AA26: S02 | DZ26: S17 | EP26: XS38 | FH26: XS10 | FI26: =Z43 -> FREE | FJ26: 80
K27: FREE | AQ27: FREE | DK27: FREE | FH27: XS11 | FI27: =AQ27 -> FREE | FJ27: 80
AA28: FREE | BF28: M02 | BU28: S10 | CF28: S12 | CU28: M13 | DZ28: FREE | EP28: FREE | FH28: XS12 | FI28: =AZ24 -> FREE | FJ28: 80
FH29: XS13 | FI29: =J60 -> FREE | FJ29: 80
BF30: FREE | BU30: FREE | CF30: FREE | CU30: FREE | FH30: XS14 | FI30: =BN11 -> FREE | FJ30: 80
FH31: XS15 | FI31: =T67 -> FREE | FJ31: 80
FH32: XS16 | FI32: =BN22 -> FREE | FJ32: 80
AY33: S05 | DB33: S14 | EX33: SOY1 | FH33: XS17 | FI33: =C101 -> FREE | FJ33: 80
S34: XS05 | BL34: S02 | EH34: XS37 | FH34: XS18 | FI34: =J94 -> FREE | FJ34: 80
B35: SOY4 | AY35: FREE | CN35: S04 | DB35: FREE | FH35: XS19 | FI35: =T91 -> FREE | FJ35: 80
S36: FREE | BL36: FREE | BZ36: L03 | EH36: FREE | FH36: XS20 | FI36: =CM22 -> FREE | FJ36: 80
CN37: FREE | FH37: XS21 | FI37: =CL11 -> FREE | FJ37: 80
BZ38: FREE | FH38: XS22 | FI38: =CZ5 -> FREE | FJ38: 80
FH39: XS23 | FI39: =R112 -> FREE | FJ39: 80
BF40: M05 | BS40: M07 | CU40: M17 | FH40: XS24 | FI40: =X106 -> FREE | FJ40: 80
Z41: XS10 | AQ41: L01 | CH41: M12 | DJ41: L07 | EA41: XS36 | FH41: XS25 | FI41: =DB23 -> FREE | FJ41: 80
...

Sheet Среда 2
AG2: SOY3 | DS2: SOY2 | EM2: Для переноса данных с прошлого дня копируем таблицу в пределах границ Таблица сделана в штате 463 Союзом Carent Morte(CRT)
BB3: XS08 | BZ3: S06 | CZ3: XS22 | FG3: Союзы | FH3: Нефти по дняM недели заработали | FT3: ИТОГО | FY3: 2
FH4: Вторник 1 | FI4: Среда 2 | FJ4: Четверг 3 | FK4: Пятница 4 | FL4: Суббота 5 | FM4: Воскресенье 6 | FN4: Понедельник 7 | FO4: Вторник 8 | FP4: Среда 9 | FQ4: Четверг 10 | FR4: Пятница 11 | FS4: Суббота 12
BB5: FREE | BZ5: FREE | CZ5: FREE | FG5: SOY1 | FH5: ='Вторник 1'!FH5 -> 0 | FI5: =SUMIF($FI$17:$FI$181,FG5,$FJ$17:$FJ$181) -> 0 | FT5: =SUM(FH5:FS5) -> 0
FG6: SOY2 | FH6: ='Вторник 1'!FH6 -> 0 | FI6: =SUMIF($FI$17:$FI$181,FG6,$FJ$17:$FJ$181) -> 0 | FT6: =SUM(FH6:FS6) -> 0
FG7: SOY3 | FH7: ='Вторник 1'!FH7 -> 0 | FI7: =SUMIF($FI$17:$FI$181,FG7,$FJ$17:$FJ$181) -> 0 | FT7: =SUM(FH7:FS7) -> 0
FG8: SOY4 | FH8: ='Вторник 1'!FH8 -> 0 | FI8: =SUMIF($FI$17:$FI$181,FG8,$FJ$17:$FJ$181) -> 0 | FT8: =SUM(FH8:FS8) -> 0
BN9: XS14 | CL9: XS21 | FG9: SOY5 | FH9: ='Вторник 1'!FH9 -> 0 | FI9: =SUMIF($FI$17:$FI$181,FG9,$FJ$17:$FJ$181) -> 0 | FT9: =SUM(FH9:FS9) -> 0
Z10: XS02 | EA10: XS32 | FG10: SOY6 | FH10: ='Вторник 1'!FH10 -> 0 | FI10: =SUMIF($FI$17:$FI$181,FG10,$FJ$17:$FJ$181) -> 0 | FT10: =SUM(FH10:FS10) -> 0
BN11: FREE | BZ11: S08 | CL11: FREE | FG11: SOY7 | FH11: ='Вторник 1'!FH11 -> 0 | FI11: =SUMIF($FI$17:$FI$181,FG11,$FJ$17:$FJ$181) -> 0 | FT11: =SUM(FH11:FS11) -> 0
Z12: FREE | EA12: FREE | FG12: SOY8 | FH12: ='Вторник 1'!FH12 -> 0 | FI12: =SUMIF($FI$17:$FI$181,FG12,$FJ$17:$FJ$181) -> 0 | FT12: =SUM(FH12:FS12) -> 0
BZ13: FREE | DI13: XS26 | FG13: FREE
AS14: XS07
DI15: FREE | FG15: Точка добычи | FI15: Cоюз | FJ15: Дают очков
AS16: FREE
FG17: ЛОГОВА | FH17: XS01 | FI17: =K27 -> FREE | FJ17: 80
S18: S01 | AI18: XS06 | EH18: S18 | FH18: XS02 | FI18: =Z12 -> FREE | FJ18: 80
DS19: XS31 | FH19: XS03 | FI19: =C52 -> FREE | FJ19: 80
S20: FREE | AI20: FREE | BN20: XS16 | CM20: XS20 | EH20: FREE | FH20: XS04 | FI20: =O44 -> FREE | FJ20: 80
DB21: XS25 | DS21: FREE | FH21: XS05 | FI21: =S36 -> FREE | FJ21: 80
AZ22: XS12 | BN22: FREE | CM22: FREE | FH22: XS06 | FI22: =AI20 -> FREE | FJ22: 80
DB23: FREE | FH23: XS07 | FI23: =AS16 -> FREE | FJ23: 80
AZ24: FREE | FH24: XS08 | FI24: =BB5 -> FREE | FJ24: 80
K25: XS01 | AQ25: XS11 | DK25: XS30 | FH25: XS09 | FI25: =V51 -> FREE | FJ25: 80
AA26: S02 | DZ26: S17 | EP26: XS38 | FH26: XS10 | FI26: =Z43 -> FREE | FJ26: 80
K27: FREE | AQ27: FREE | DK27: FREE | FH27: XS11 | FI27: =AQ27 -> FREE | FJ27: 80
AA28: FREE | BF28: M02 | BU28: S10 | CF28: S12 | CU28: M13 | DZ28: FREE | EP28: FREE | FH28: XS12 | FI28: =AZ24 -> FREE | FJ28: 80
FH29: XS13 | FI29: =J60 -> FREE | FJ29: 80
BF30: FREE | BU30: FREE | CF30: FREE | CU30: FREE | FH30: XS14 | FI30: =BN11 -> FREE | FJ30: 80
FH31: XS15 | FI31: =T67 -> FREE | FJ31: 80
FH32: XS16 | FI32: =BN22 -> FREE | FJ32: 80
AY33: S05 | DB33: S14 | EX33: SOY1 | FH33: XS17 | FI33: =C101 -> FREE | FJ33: 80
S34: XS05 | BL34: S02 | EH34: XS37 | FH34: XS18 | FI34: =J94 -> FREE | FJ34: 80
B35: SOY4 | AY35: FREE | CN35: S04 | DB35: FREE | FH35: XS19 | FI35: =T91 -> FREE | FJ35: 80
S36: FREE | BL36: FREE | BZ36: L03 | EH36: FREE | FH36: XS20 | FI36: =CM22 -> FREE | FJ36: 80
CN37: FREE | FH37: XS21 | FI37: =CL11 -> FREE | FJ37: 80
BZ38: FREE | FH38: XS22 | FI38: =CZ5 -> FREE | FJ38: 80
FH39: XS23 | FI39: =R112 -> FREE | FJ39: 80
BF40: M05 | BS40: M07 | CU40: M17 | FH40: XS24 | FI40: =X106 -> FREE | FJ40: 80
Z41: XS10 | AQ41: L01 | CH41: M12 | DJ41: L07 | EA41: XS36 | FH41: XS25 | FI41: =DB23 -> FREE | FJ41: 80
...

Sheet Четверг 3
AG2: SOY3 | DS2: SOY2 | EM2: Для переноса данных с прошлого дня копируем таблицу в пределах границ Таблица сделана в штате 463 Союзом Carent Morte(CRT)
BB3: XS08 | BZ3: S06 | CZ3: XS22 | FG3: Союзы | FH3: Нефти по дняM недели заработали | FT3: ИТОГО | FY3: 2
FH4: Вторник 1 | FI4: Среда 2 | FJ4: Четверг 3 | FK4: Пятница 4 | FL4: Суббота 5 | FM4: Воскресенье 6 | FN4: Понедельник 7 | FO4: Вторник 8 | FP4: Среда 9 | FQ4: Четверг 10 | FR4: Пятница 11 | FS4: Суббота 12
BB5: FREE | BZ5: FREE | CZ5: FREE | FG5: SOY1 | FH5: ='Вторник 1'!FH5 -> 0 | FI5: ='Среда 2'!FI5 -> 0 | FJ5: =SUMIF($FI$17:$FI$181,FG5,$FJ$17:$FJ$181) -> 0 | FT5: =SUM(FH5:FS5) -> 0
FG6: SOY2 | FH6: ='Вторник 1'!FH6 -> 0 | FI6: ='Среда 2'!FI6 -> 0 | FJ6: =SUMIF($FI$17:$FI$181,FG6,$FJ$17:$FJ$181) -> 0 | FT6: =SUM(FH6:FS6) -> 0
FG7: SOY3 | FH7: ='Вторник 1'!FH7 -> 0 | FI7: ='Среда 2'!FI7 -> 0 | FJ7: =SUMIF($FI$17:$FI$181,FG7,$FJ$17:$FJ$181) -> 0 | FT7: =SUM(FH7:FS7) -> 0
FG8: SOY4 | FH8: ='Вторник 1'!FH8 -> 0 | FI8: ='Среда 2'!FI8 -> 0 | FJ8: =SUMIF($FI$17:$FI$181,FG8,$FJ$17:$FJ$181) -> 0 | FT8: =SUM(FH8:FS8) -> 0
BN9: XS14 | CL9: XS21 | FG9: SOY5 | FH9: ='Вторник 1'!FH9 -> 0 | FI9: ='Среда 2'!FI9 -> 0 | FJ9: =SUMIF($FI$17:$FI$181,FG9,$FJ$17:$FJ$181) -> 0 | FT9: =SUM(FH9:FS9) -> 0
Z10: XS02 | EA10: XS32 | FG10: SOY6 | FH10: ='Вторник 1'!FH10 -> 0 | FI10: ='Среда 2'!FI10 -> 0 | FJ10: =SUMIF($FI$17:$FI$181,FG10,$FJ$17:$FJ$181) -> 0 | FT10: =SUM(FH10:FS10) -> 0
BN11: FREE | BZ11: S08 | CL11: FREE | FG11: SOY7 | FH11: ='Вторник 1'!FH11 -> 0 | FI11: ='Среда 2'!FI11 -> 0 | FJ11: =SUMIF($FI$17:$FI$181,FG11,$FJ$17:$FJ$181) -> 0 | FT11: =SUM(FH11:FS11) -> 0
Z12: FREE | EA12: FREE | FG12: SOY8 | FH12: ='Вторник 1'!FH12 -> 0 | FI12: ='Среда 2'!FI12 -> 0 | FJ12: =SUMIF($FI$17:$FI$181,FG12,$FJ$17:$FJ$181) -> 0 | FT12: =SUM(FH12:FS12) -> 0
BZ13: FREE | DI13: XS26 | FG13: FREE
AS14: XS07
DI15: FREE | FG15: Точка добычи | FI15: Cоюз | FJ15: Дают очков
AS16: FREE
FG17: ЛОГОВА | FH17: XS01 | FI17: =K27 -> FREE | FJ17: 80
S18: S01 | AI18: XS06 | EH18: S18 | FH18: XS02 | FI18: =Z12 -> FREE | FJ18: 80
DS19: XS31 | FH19: XS03 | FI19: =C52 -> FREE | FJ19: 80
S20: FREE | AI20: FREE | BN20: XS16 | CM20: XS20 | EH20: FREE | FH20: XS04 | FI20: =O44 -> FREE | FJ20: 80
DB21: XS25 | DS21: FREE | FH21: XS05 | FI21: =S36 -> FREE | FJ21: 80
AZ22: XS12 | BN22: FREE | CM22: FREE | FH22: XS06 | FI22: =AI20 -> FREE | FJ22: 80
DB23: FREE | FH23: XS07 | FI23: =AS16 -> FREE | FJ23: 80
AZ24: FREE | FH24: XS08 | FI24: =BB5 -> FREE | FJ24: 80
K25: XS01 | AQ25: XS11 | DK25: XS30 | FH25: XS09 | FI25: =V51 -> FREE | FJ25: 80
AA26: S02 | DZ26: S17 | EP26: XS38 | FH26: XS10 | FI26: =Z43 -> FREE | FJ26: 80
K27: FREE | AQ27: FREE | DK27: FREE | FH27: XS11 | FI27: =AQ27 -> FREE | FJ27: 80
AA28: FREE | BF28: M02 | BU28: S10 | CF28: S12 | CU28: M13 | DZ28: FREE | EP28: FREE | FH28: XS12 | FI28: =AZ24 -> FREE | FJ28: 80
FH29: XS13 | FI29: =J60 -> FREE | FJ29: 80
BF30: FREE | BU30: FREE | CF30: FREE | CU30: FREE | FH30: XS14 | FI30: =BN11 -> FREE | FJ30: 80
FH31: XS15 | FI31: =T67 -> FREE | FJ31: 80
FH32: XS16 | FI32: =BN22 -> FREE | FJ32: 80
AY33: S05 | DB33: S14 | EX33: SOY1 | FH33: XS17 | FI33: =C101 -> FREE | FJ33: 80
S34: XS05 | BL34: S02 | EH34: XS37 | FH34: XS18 | FI34: =J94 -> FREE | FJ34: 80
B35: SOY4 | AY35: FREE | CN35: S04 | DB35: FREE | FH35: XS19 | FI35: =T91 -> FREE | FJ35: 80
S36: FREE | BL36: FREE | BZ36: L03 | EH36: FREE | FH36: XS20 | FI36: =CM22 -> FREE | FJ36: 80
CN37: FREE | FH37: XS21 | FI37: =CL11 -> FREE | FJ37: 80
BZ38: FREE | FH38: XS22 | FI38: =CZ5 -> FREE | FJ38: 80
FH39: XS23 | FI39: =R112 -> FREE | FJ39: 80
BF40: M05 | BS40: M07 | CU40: M17 | FH40: XS24 | FI40: =X106 -> FREE | FJ40: 80
Z41: XS10 | AQ41: L01 | CH41: M12 | DJ41: L07 | EA41: XS36 | FH41: XS25 | FI41: =DB23 -> FREE | FJ41: 80
...

Sheet Пятница 4
AG2: SOY3 | DS2: SOY2 | EM2: Для переноса данных с прошлого дня копируем таблицу в пределах границ Таблица сделана в штате 463 Союзом Carent Morte(CRT)
BB3: XS08 | BZ3: S06 | CZ3: XS22 | FG3: Союзы | FH3: Нефти по дняM недели заработали | FT3: ИТОГО | FY3: 2
FH4: Вторник 1 | FI4: Среда 2 | FJ4: Четверг 3 | FK4: Пятница 4 | FL4: Суббота 5 | FM4: Воскресенье 6 | FN4: Понедельник 7 | FO4: Вторник 8 | FP4: Среда 9 | FQ4: Четверг 10 | FR4: Пятница 11 | FS4: Суббота 12
BB5: FREE | BZ5: FREE | CZ5: FREE | FG5: SOY1 | FH5: ='Вторник 1'!FH5 -> 0 | FI5: ='Среда 2'!FI5 -> 0 | FJ5: ='Четверг 3'!FJ5 -> 0 | FK5: =SUMIF($FI$17:$FI$181,FG5,$FJ$17:$FJ$181) -> 0 | FT5: =SUM(FH5:FS5) -> 0
FG6: SOY2 | FH6: ='Вторник 1'!FH6 -> 0 | FI6: ='Среда 2'!FI6 -> 0 | FJ6: ='Четверг 3'!FJ6 -> 0 | FK6: =SUMIF($FI$17:$FI$181,FG6,$FJ$17:$FJ$181) -> 0 | FT6: =SUM(FH6:FS6) -> 0
FG7: SOY3 | FH7: ='Вторник 1'!FH7 -> 0 | FI7: ='Среда 2'!FI7 -> 0 | FJ7: ='Четверг 3'!FJ7 -> 0 | FK7: =SUMIF($FI$17:$FI$181,FG7,$FJ$17:$FJ$181) -> 0 | FT7: =SUM(FH7:FS7) -> 0
FG8: SOY4 | FH8: ='Вторник 1'!FH8 -> 0 | FI8: ='Среда 2'!FI8 -> 0 | FJ8: ='Четверг 3'!FJ8 -> 0 | FK8: =SUMIF($FI$17:$FI$181,FG8,$FJ$17:$FJ$181) -> 0 | FT8: =SUM(FH8:FS8) -> 0
BN9: XS14 | CL9: XS21 | FG9: SOY5 | FH9: ='Вторник 1'!FH9 -> 0 | FI9: ='Среда 2'!FI9 -> 0 | FJ9: ='Четверг 3'!FJ9 -> 0 | FK9: =SUMIF($FI$17:$FI$181,FG9,$FJ$17:$FJ$181) -> 0 | FT9: =SUM(FH9:FS9) -> 0
Z10: XS02 | EA10: XS32 | FG10: SOY6 | FH10: ='Вторник 1'!FH10 -> 0 | FI10: ='Среда 2'!FI10 -> 0 | FJ10: ='Четверг 3'!FJ10 -> 0 | FK10: =SUMIF($FI$17:$FI$181,FG10,$FJ$17:$FJ$181) -> 0 | FT10: =SUM(FH10:FS10) -> 0
BN11: FREE | BZ11: S08 | CL11: FREE | FG11: SOY7 | FH11: ='Вторник 1'!FH11 -> 0 | FI11: ='Среда 2'!FI11 -> 0 | FJ11: ='Четверг 3'!FJ11 -> 0 | FK11: =SUMIF($FI$17:$FI$181,FG11,$FJ$17:$FJ$181) -> 0 | FT11: =SUM(FH11:FS11) -> 0
Z12: FREE | EA12: FREE | FG12: SOY8 | FH12: ='Вторник 1'!FH12 -> 0 | FI12: ='Среда 2'!FI12 -> 0 | FJ12: ='Четверг 3'!FJ12 -> 0 | FK12: =SUMIF($FI$17:$FI$181,FG12,$FJ$17:$FJ$181) -> 0 | FT12: =SUM(FH12:FS12) -> 0
BZ13: FREE | DI13: XS26 | FG13: FREE
AS14: XS07
DI15: FREE | FG15: Точка добычи | FI15: Cоюз | FJ15: Дают очков
AS16: FREE
FG17: ЛОГОВА | FH17: XS01 | FI17: =K27 -> FREE | FJ17: 80
S18: S01 | AI18: XS06 | EH18: S18 | FH18: XS02 | FI18: =Z12 -> FREE | FJ18: 80
DS19: XS31 | FH19: XS03 | FI19: =C52 -> FREE | FJ19: 80
S20: FREE | AI20: FREE | BN20: XS16 | CM20: XS20 | EH20: FREE | FH20: XS04 | FI20: =O44 -> FREE | FJ20: 80
DB21: XS25 | DS21: FREE | FH21: XS05 | FI21: =S36 -> FREE | FJ21: 80
AZ22: XS12 | BN22: FREE | CM22: FREE | FH22: XS06 | FI22: =AI20 -> FREE | FJ22: 80
DB23: FREE | FH23: XS07 | FI23: =AS16 -> FREE | FJ23: 80
AZ24: FREE | FH24: XS08 | FI24: =BB5 -> FREE | FJ24: 80
K25: XS01 | AQ25: XS11 | DK25: XS30 | FH25: XS09 | FI25: =V51 -> FREE | FJ25: 80
AA26: S02 | DZ26: S17 | EP26: XS38 | FH26: XS10 | FI26: =Z43 -> FREE | FJ26: 80
K27: FREE | AQ27: FREE | DK27: FREE | FH27: XS11 | FI27: =AQ27 -> FREE | FJ27: 80
AA28: FREE | BF28: M02 | BU28: S10 | CF28: S12 | CU28: M13 | DZ28: FREE | EP28: FREE | FH28: XS12 | FI28: =AZ24 -> FREE | FJ28: 80
FH29: XS13 | FI29: =J60 -> FREE | FJ29: 80
BF30: FREE | BU30: FREE | CF30: FREE | CU30: FREE | FH30: XS14 | FI30: =BN11 -> FREE | FJ30: 80
FH31: XS15 | FI31: =T67 -> FREE | FJ31: 80
FH32: XS16 | FI32: =BN22 -> FREE | FJ32: 80
AY33: S05 | DB33: S14 | EX33: SOY1 | FH33: XS17 | FI33: =C101 -> FREE | FJ33: 80
S34: XS05 | BL34: S02 | EH34: XS37 | FH34: XS18 | FI34: =J94 -> FREE | FJ34: 80
B35: SOY4 | AY35: FREE | CN35: S04 | DB35: FREE | FH35: XS19 | FI35: =T91 -> FREE | FJ35: 80
S36: FREE | BL36: FREE | BZ36: L03 | EH36: FREE | FH36: XS20 | FI36: =CM22 -> FREE | FJ36: 80
CN37: FREE | FH37: XS21 | FI37: =CL11 -> FREE | FJ37: 80
BZ38: FREE | FH38: XS22 | FI38: =CZ5 -> FREE | FJ38: 80
FH39: XS23 | FI39: =R112 -> FREE | FJ39: 80
BF40: M05 | BS40: M07 | CU40: M17 | FH40: XS24 | FI40: =X106 -> FREE | FJ40: 80
Z41: XS10 | AQ41: L01 | CH41: M12 | DJ41: L07 | EA41: XS36 | FH41: XS25 | FI41: =DB23 -> FREE | FJ41: 80
...

Sheet Суббота 5
AG2: SOY3 | DS2: SOY2 | EM2: Для переноса данных с прошлого дня копируем таблицу в пределах границ Таблица сделана в штате 463 Союзом Carent Morte(CRT)
BB3: XS08 | BZ3: S06 | CZ3: XS22 | FG3: Союзы | FH3: Нефти по дняM недели заработали | FT3: ИТОГО | FY3: 2
FH4: Вторник 1 | FI4: Среда 2 | FJ4: Четверг 3 | FK4: Пятница 4 | FL4: Суббота 5 | FM4: Воскресенье 6 | FN4: Понедельник 7 | FO4: Вторник 8 | FP4: Среда 9 | FQ4: Четверг 10 | FR4: Пятница 11 | FS4: Суббота 12
BB5: FREE | BZ5: FREE | CZ5: FREE | FG5: SOY1 | FH5: ='Вторник 1'!FH5 -> 0 | FI5: ='Среда 2'!FI5 -> 0 | FJ5: ='Четверг 3'!FJ5 -> 0 | FK5: ='Пятница 4'!FK5 -> 0 | FL5: =SUMIF($FI$17:$FI$181,FG5,$FJ$17:$FJ$181) -> 0 | FT5: =SUM(FH5:FS5) -> 0
FG6: SOY2 | FH6: ='Вторник 1'!FH6 -> 0 | FI6: ='Среда 2'!FI6 -> 0 | FJ6: ='Четверг 3'!FJ6 -> 0 | FK6: ='Пятница 4'!FK6 -> 0 | FL6: =SUMIF($FI$17:$FI$181,FG6,$FJ$17:$FJ$181) -> 0 | FT6: =SUM(FH6:FS6) -> 0
FG7: SOY3 | FH7: ='Вторник 1'!FH7 -> 0 | FI7: ='Среда 2'!FI7 -> 0 | FJ7: ='Четверг 3'!FJ7 -> 0 | FK7: ='Пятница 4'!FK7 -> 0 | FL7: =SUMIF($FI$17:$FI$181,FG7,$FJ$17:$FJ$181) -> 0 | FT7: =SUM(FH7:FS7) -> 0
FG8: SOY4 | FH8: ='Вторник 1'!FH8 -> 0 | FI8: ='Среда 2'!FI8 -> 0 | FJ8: ='Четверг 3'!FJ8 -> 0 | FK8: ='Пятница 4'!FK8 -> 0 | FL8: =SUMIF($FI$17:$FI$181,FG8,$FJ$17:$FJ$181) -> 0 | FT8: =SUM(FH8:FS8) -> 0
BN9: XS14 | CL9: XS21 | FG9: SOY5 | FH9: ='Вторник 1'!FH9 -> 0 | FI9: ='Среда 2'!FI9 -> 0 | FJ9: ='Четверг 3'!FJ9 -> 0 | FK9: ='Пятница 4'!FK9 -> 0 | FL9: =SUMIF($FI$17:$FI$181,FG9,$FJ$17:$FJ$181) -> 0 | FT9: =SUM(FH9:FS9) -> 0
Z10: XS02 | EA10: XS32 | FG10: SOY6 | FH10: ='Вторник 1'!FH10 -> 0 | FI10: ='Среда 2'!FI10 -> 0 | FJ10: ='Четверг 3'!FJ10 -> 0 | FK10: ='Пятница 4'!FK10 -> 0 | FL10: =SUMIF($FI$17:$FI$181,FG10,$FJ$17:$FJ$181) -> 0 | FT10: =SUM(FH10:FS10) -> 0
BN11: FREE | BZ11: S08 | CL11: FREE | FG11: SOY7 | FH11: ='Вторник 1'!FH11 -> 0 | FI11: ='Среда 2'!FI11 -> 0 | FJ11: ='Четверг 3'!FJ11 -> 0 | FK11: ='Пятница 4'!FK11 -> 0 | FL11: =SUMIF($FI$17:$FI$181,FG11,$FJ$17:$FJ$181) -> 0 | FT11: =SUM(FH11:FS11) -> 0
Z12: FREE | EA12: FREE | FG12: SOY8 | FH12: ='Вторник 1'!FH12 -> 0 | FI12: ='Среда 2'!FI12 -> 0 | FJ12: ='Четверг 3'!FJ12 -> 0 | FK12: ='Пятница 4'!FK12 -> 0 | FL12: =SUMIF($FI$17:$FI$181,FG12,$FJ$17:$FJ$181) -> 0 | FT12: =SUM(FH12:FS12) -> 0
BZ13: FREE | DI13: XS26 | FG13: FREE
AS14: XS07
DI15: FREE | FG15: Точка добычи | FI15: Cоюз | FJ15: Дают очков
AS16: FREE
FG17: ЛОГОВА | FH17: XS01 | FI17: =K27 -> FREE | FJ17: 80
S18: S01 | AI18: XS06 | EH18: S18 | FH18: XS02 | FI18: =Z12 -> FREE | FJ18: 80
DS19: XS31 | FH19: XS03 | FI19: =C52 -> FREE | FJ19: 80
S20: FREE | AI20: FREE | BN20: XS16 | CM20: XS20 | EH20: FREE | FH20: XS04 | FI20: =O44 -> FREE | FJ20: 80
DB21: XS25 | DS21: FREE | FH21: XS05 | FI21: =S36 -> FREE | FJ21: 80
AZ22: XS12 | BN22: FREE | CM22: FREE | FH22: XS06 | FI22: =AI20 -> FREE | FJ22: 80
DB23: FREE | FH23: XS07 | FI23: =AS16 -> FREE | FJ23: 80
AZ24: FREE | FH24: XS08 | FI24: =BB5 -> FREE | FJ24: 80
K25: XS01 | AQ25: XS11 | DK25: XS30 | FH25: XS09 | FI25: =V51 -> FREE | FJ25: 80
AA26: S02 | DZ26: S17 | EP26: XS38 | FH26: XS10 | FI26: =Z43 -> FREE | FJ26: 80
K27: FREE | AQ27: FREE | DK27: FREE | FH27: XS11 | FI27: =AQ27 -> FREE | FJ27: 80
AA28: FREE | BF28: M02 | BU28: S10 | CF28: S12 | CU28: M13 | DZ28: FREE | EP28: FREE | FH28: XS12 | FI28: =AZ24 -> FREE | FJ28: 80
FH29: XS13 | FI29: =J60 -> FREE | FJ29: 80
BF30: FREE | BU30: FREE | CF30: FREE | CU30: FREE | FH30: XS14 | FI30: =BN11 -> FREE | FJ30: 80
FH31: XS15 | FI31: =T67 -> FREE | FJ31: 80
FH32: XS16 | FI32: =BN22 -> FREE | FJ32: 80
AY33: S05 | DB33: S14 | EX33: SOY1 | FH33: XS17 | FI33: =C101 -> FREE | FJ33: 80
S34: XS05 | BL34: S02 | EH34: XS37 | FH34: XS18 | FI34: =J94 -> FREE | FJ34: 80
B35: SOY4 | AY35: FREE | CN35: S04 | DB35: FREE | FH35: XS19 | FI35: =T91 -> FREE | FJ35: 80
S36: FREE | BL36: FREE | BZ36: L03 | EH36: FREE | FH36: XS20 | FI36: =CM22 -> FREE | FJ36: 80
CN37: FREE | FH37: XS21 | FI37: =CL11 -> FREE | FJ37: 80
BZ38: FREE | FH38: XS22 | FI38: =CZ5 -> FREE | FJ38: 80
FH39: XS23 | FI39: =R112 -> FREE | FJ39: 80
BF40: M05 | BS40: M07 | CU40: M17 | FH40: XS24 | FI40: =X106 -> FREE | FJ40: 80
Z41: XS10 | AQ41: L01 | CH41: M12 | DJ41: L07 | EA41: XS36 | FH41: XS25 | FI41: =DB23 -> FREE | FJ41: 80
...

Sheet Воскресенье 6
AG2: SOY3 | DS2: SOY2 | EM2: Для переноса данных с прошлого дня копируем таблицу в пределах границ Таблица сделана в штате 463 Союзом Carent Morte(CRT)
BB3: XS08 | BZ3: S06 | CZ3: XS22 | FG3: Союзы | FH3: Нефти по дняM недели заработали | FT3: ИТОГО | FY3: 2
FH4: Вторник 1 | FI4: Среда 2 | FJ4: Четверг 3 | FK4: Пятница 4 | FL4: Суббота 5 | FM4: Воскресенье 6 | FN4: Понедельник 7 | FO4: Вторник 8 | FP4: Среда 9 | FQ4: Четверг 10 | FR4: Пятница 11 | FS4: Суббота 12
BB5: FREE | BZ5: FREE | CZ5: FREE | FG5: SOY1 | FH5: ='Вторник 1'!FH5 -> 0 | FI5: ='Среда 2'!FI5 -> 0 | FJ5: ='Четверг 3'!FJ5 -> 0 | FK5: ='Пятница 4'!FK5 -> 0 | FL5: ='Суббота 5'!FL5 -> 0 | FM5: =SUMIF($FI$17:$FI$181,FG5,$FJ$17:$FJ$181) -> 0 | FT5: =SUM(FH5:FS5) -> 0
FG6: SOY2 | FH6: ='Вторник 1'!FH6 -> 0 | FI6: ='Среда 2'!FI6 -> 0 | FJ6: ='Четверг 3'!FJ6 -> 0 | FK6: ='Пятница 4'!FK6 -> 0 | FL6: ='Суббота 5'!FL6 -> 0 | FM6: =SUMIF($FI$17:$FI$181,FG6,$FJ$17:$FJ$181) -> 0 | FT6: =SUM(FH6:FS6) -> 0
FG7: SOY3 | FH7: ='Вторник 1'!FH7 -> 0 | FI7: ='Среда 2'!FI7 -> 0 | FJ7: ='Четверг 3'!FJ7 -> 0 | FK7: ='Пятница 4'!FK7 -> 0 | FL7: ='Суббота 5'!FL7 -> 0 | FM7: =SUMIF($FI$17:$FI$181,FG7,$FJ$17:$FJ$181) -> 0 | FT7: =SUM(FH7:FS7) -> 0
FG8: SOY4 | FH8: ='Вторник 1'!FH8 -> 0 | FI8: ='Среда 2'!FI8 -> 0 | FJ8: ='Четверг 3'!FJ8 -> 0 | FK8: ='Пятница 4'!FK8 -> 0 | FL8: ='Суббота 5'!FL8 -> 0 | FM8: =SUMIF($FI$17:$FI$181,FG8,$FJ$17:$FJ$181) -> 0 | FT8: =SUM(FH8:FS8) -> 0
BN9: XS14 | CL9: XS21 | FG9: SOY5 | FH9: ='Вторник 1'!FH9 -> 0 | FI9: ='Среда 2'!FI9 -> 0 | FJ9: ='Четверг 3'!FJ9 -> 0 | FK9: ='Пятница 4'!FK9 -> 0 | FL9: ='Суббота 5'!FL9 -> 0 | FM9: =SUMIF($FI$17:$FI$181,FG9,$FJ$17:$FJ$181) -> 0 | FT9: =SUM(FH9:FS9) -> 0
Z10: XS02 | EA10: XS32 | FG10: SOY6 | FH10: ='Вторник 1'!FH10 -> 0 | FI10: ='Среда 2'!FI10 -> 0 | FJ10: ='Четверг 3'!FJ10 -> 0 | FK10: ='Пятница 4'!FK10 -> 0 | FL10: ='Суббота 5'!FL10 -> 0 | FM10: =SUMIF($FI$17:$FI$181,FG10,$FJ$17:$FJ$181) -> 0 | FT10: =SUM(FH10:FS10) -> 0
BN11: FREE | BZ11: S08 | CL11: FREE | FG11: SOY7 | FH11: ='Вторник 1'!FH11 -> 0 | FI11: ='Среда 2'!FI11 -> 0 | FJ11: ='Четверг 3'!FJ11 -> 0 | FK11: ='Пятница 4'!FK11 -> 0 | FL11: ='Суббота 5'!FL11 -> 0 | FM11: =SUMIF($FI$17:$FI$181,FG11,$FJ$17:$FJ$181) -> 0 | FT11: =SUM(FH11:FS11) -> 0
Z12: FREE | EA12: FREE | FG12: SOY8 | FH12: ='Вторник 1'!FH12 -> 0 | FI12: ='Среда 2'!FI12 -> 0 | FJ12: ='Четверг 3'!FJ12 -> 0 | FK12: ='Пятница 4'!FK12 -> 0 | FL12: ='Суббота 5'!FL12 -> 0 | FM12: =SUMIF($FI$17:$FI$181,FG12,$FJ$17:$FJ$181) -> 0 | FT12: =SUM(FH12:FS12) -> 0
BZ13: FREE | DI13: XS26 | FG13: FREE
AS14: XS07
DI15: FREE | FG15: Точка добычи | FI15: Cоюз | FJ15: Дают очков
AS16: FREE
FG17: ЛОГОВА | FH17: XS01 | FI17: =K27 -> FREE | FJ17: 80
S18: S01 | AI18: XS06 | EH18: S18 | FH18: XS02 | FI18: =Z12 -> FREE | FJ18: 80
DS19: XS31 | FH19: XS03 | FI19: =C52 -> FREE | FJ19: 80
S20: FREE | AI20: FREE | BN20: XS16 | CM20: XS20 | EH20: FREE | FH20: XS04 | FI20: =O44 -> FREE | FJ20: 80
DB21: XS25 | DS21: FREE | FH21: XS05 | FI21: =S36 -> FREE | FJ21: 80
AZ22: XS12 | BN22: FREE | CM22: FREE | FH22: XS06 | FI22: =AI20 -> FREE | FJ22: 80
DB23: FREE | FH23: XS07 | FI23: =AS16 -> FREE | FJ23: 80
AZ24: FREE | FH24: XS08 | FI24: =BB5 -> FREE | FJ24: 80
K25: XS01 | AQ25: XS11 | DK25: XS30 | FH25: XS09 | FI25: =V51 -> FREE | FJ25: 80
AA26: S02 | DZ26: S17 | EP26: XS38 | FH26: XS10 | FI26: =Z43 -> FREE | FJ26: 80
K27: FREE | AQ27: FREE | DK27: FREE | FH27: XS11 | FI27: =AQ27 -> FREE | FJ27: 80
AA28: FREE | BF28: M02 | BU28: S10 | CF28: S12 | CU28: M13 | DZ28: FREE | EP28: FREE | FH28: XS12 | FI28: =AZ24 -> FREE | FJ28: 80
FH29: XS13 | FI29: =J60 -> FREE | FJ29: 80
BF30: FREE | BU30: FREE | CF30: FREE | CU30: FREE | FH30: XS14 | FI30: =BN11 -> FREE | FJ30: 80
FH31: XS15 | FI31: =T67 -> FREE | FJ31: 80
FH32: XS16 | FI32: =BN22 -> FREE | FJ32: 80
AY33: S05 | DB33: S14 | EX33: SOY1 | FH33: XS17 | FI33: =C101 -> FREE | FJ33: 80
S34: XS05 | BL34: S02 | EH34: XS37 | FH34: XS18 | FI34: =J94 -> FREE | FJ34: 80
B35: SOY4 | AY35: FREE | CN35: S04 | DB35: FREE | FH35: XS19 | FI35: =T91 -> FREE | FJ35: 80
S36: FREE | BL36: FREE | BZ36: L03 | EH36: FREE | FH36: XS20 | FI36: =CM22 -> FREE | FJ36: 80
CN37: FREE | FH37: XS21 | FI37: =CL11 -> FREE | FJ37: 80
BZ38: FREE | FH38: XS22 | FI38: =CZ5 -> FREE | FJ38: 80
FH39: XS23 | FI39: =R112 -> FREE | FJ39: 80
BF40: M05 | BS40: M07 | CU40: M17 | FH40: XS24 | FI40: =X106 -> FREE | FJ40: 80
Z41: XS10 | AQ41: L01 | CH41: M12 | DJ41: L07 | EA41: XS36 | FH41: XS25 | FI41: =DB23 -> FREE | FJ41: 80
...

Sheet Понедельник 7
AG2: SOY3 | DS2: SOY2 | EM2: Для переноса данных с прошлого дня копируем таблицу в пределах границ Таблица сделана в штате 463 Союзом Carent Morte(CRT)
BB3: XS08 | BZ3: S06 | CZ3: XS22 | FG3: Союзы | FH3: Нефти по дняM недели заработали | FT3: ИТОГО | FY3: 2
FH4: Вторник 1 | FI4: Среда 2 | FJ4: Четверг 3 | FK4: Пятница 4 | FL4: Суббота 5 | FM4: Воскресенье 6 | FN4: Понедельник 7 | FO4: Вторник 8 | FP4: Среда 9 | FQ4: Четверг 10 | FR4: Пятница 11 | FS4: Суббота 12
BB5: FREE | BZ5: FREE | CZ5: FREE | FG5: SOY1 | FH5: ='Вторник 1'!FH5 -> 0 | FI5: ='Среда 2'!FI5 -> 0 | FJ5: ='Четверг 3'!FJ5 -> 0 | FK5: ='Пятница 4'!FK5 -> 0 | FL5: ='Суббота 5'!FL5 -> 0 | FM5: ='Воскресенье 6'!FM5 -> 0 | FN5: =SUMIF($FI$17:$FI$181,FG5,$FJ$17:$FJ$181) -> 0 | FT5: =SUM(FH5:FS5) -> 0
FG6: SOY2 | FH6: ='Вторник 1'!FH6 -> 0 | FI6: ='Среда 2'!FI6 -> 0 | FJ6: ='Четверг 3'!FJ6 -> 0 | FK6: ='Пятница 4'!FK6 -> 0 | FL6: ='Суббота 5'!FL6 -> 0 | FM6: ='Воскресенье 6'!FM6 -> 0 | FN6: =SUMIF($FI$17:$FI$181,FG6,$FJ$17:$FJ$181) -> 0 | FT6: =SUM(FH6:FS6) -> 0
FG7: SOY3 | FH7: ='Вторник 1'!FH7 -> 0 | FI7: ='Среда 2'!FI7 -> 0 | FJ7: ='Четверг 3'!FJ7 -> 0 | FK7: ='Пятница 4'!FK7 -> 0 | FL7: ='Суббота 5'!FL7 -> 0 | FM7: ='Воскресенье 6'!FM7 -> 0 | FN7: =SUMIF($FI$17:$FI$181,FG7,$FJ$17:$FJ$181) -> 0 | FT7: =SUM(FH7:FS7) -> 0
FG8: SOY4 | FH8: ='Вторник 1'!FH8 -> 0 | FI8: ='Среда 2'!FI8 -> 0 | FJ8: ='Четверг 3'!FJ8 -> 0 | FK8: ='Пятница 4'!FK8 -> 0 | FL8: ='Суббота 5'!FL8 -> 0 | FM8: ='Воскресенье 6'!FM8 -> 0 | FN8: =SUMIF($FI$17:$FI$181,FG8,$FJ$17:$FJ$181) -> 0 | FT8: =SUM(FH8:FS8) -> 0
BN9: XS14 | CL9: XS21 | FG9: SOY5 | FH9: ='Вторник 1'!FH9 -> 0 | FI9: ='Среда 2'!FI9 -> 0 | FJ9: ='Четверг 3'!FJ9 -> 0 | FK9: ='Пятница 4'!FK9 -> 0 | FL9: ='Суббота 5'!FL9 -> 0 | FM9: ='Воскресенье 6'!FM9 -> 0 | FN9: =SUMIF($FI$17:$FI$181,FG9,$FJ$17:$FJ$181) -> 0 | FT9: =SUM(FH9:FS9) -> 0
Z10: XS02 | EA10: XS32 | FG10: SOY6 | FH10: ='Вторник 1'!FH10 -> 0 | FI10: ='Среда 2'!FI10 -> 0 | FJ10: ='Четверг 3'!FJ10 -> 0 | FK10: ='Пятница 4'!FK10 -> 0 | FL10: ='Суббота 5'!FL10 -> 0 | FM10: ='Воскресенье 6'!FM10 -> 0 | FN10: =SUMIF($FI$17:$FI$181,FG10,$FJ$17:$FJ$181) -> 0 | FT10: =SUM(FH10:FS10) -> 0
BN11: FREE | BZ11: S08 | CL11: FREE | FG11: SOY7 | FH11: ='Вторник 1'!FH11 -> 0 | FI11: ='Среда 2'!FI11 -> 0 | FJ11: ='Четверг 3'!FJ11 -> 0 | FK11: ='Пятница 4'!FK11 -> 0 | FL11: ='Суббота 5'!FL11 -> 0 | FM11: ='Воскресенье 6'!FM11 -> 0 | FN11: =SUMIF($FI$17:$FI$181,FG11,$FJ$17:$FJ$181) -> 0 | FT11: =SUM(FH11:FS11) -> 0
Z12: FREE | EA12: FREE | FG12: SOY8 | FH12: ='Вторник 1'!FH12 -> 0 | FI12: ='Среда 2'!FI12 -> 0 | FJ12: ='Четверг 3'!FJ12 -> 0 | FK12: ='Пятница 4'!FK12 -> 0 | FL12: ='Суббота 5'!FL12 -> 0 | FM12: ='Воскресенье 6'!FM12 -> 0 | FN12: =SUMIF($FI$17:$FI$181,FG12,$FJ$17:$FJ$181) -> 0 | FT12: =SUM(FH12:FS12) -> 0
BZ13: FREE | DI13: XS26 | FG13: FREE
AS14: XS07
DI15: FREE | FG15: Точка добычи | FI15: Cоюз | FJ15: Дают очков
AS16: FREE
FG17: ЛОГОВА | FH17: XS01 | FI17: =K27 -> FREE | FJ17: 80
S18: S01 | AI18: XS06 | EH18: S18 | FH18: XS02 | FI18: =Z12 -> FREE | FJ18: 80
DS19: XS31 | FH19: XS03 | FI19: =C52 -> FREE | FJ19: 80
S20: FREE | AI20: FREE | BN20: XS16 | CM20: XS20 | EH20: FREE | FH20: XS04 | FI20: =O44 -> FREE | FJ20: 80
DB21: XS25 | DS21: FREE | FH21: XS05 | FI21: =S36 -> FREE | FJ21: 80
AZ22: XS12 | BN22: FREE | CM22: FREE | FH22: XS06 | FI22: =AI20 -> FREE | FJ22: 80
DB23: FREE | FH23: XS07 | FI23: =AS16 -> FREE | FJ23: 80
AZ24: FREE | FH24: XS08 | FI24: =BB5 -> FREE | FJ24: 80
K25: XS01 | AQ25: XS11 | DK25: XS30 | FH25: XS09 | FI25: =V51 -> FREE | FJ25: 80
AA26: S02 | DZ26: S17 | EP26: XS38 | FH26: XS10 | FI26: =Z43 -> FREE | FJ26: 80
K27: FREE | AQ27: FREE | DK27: FREE | FH27: XS11 | FI27: =AQ27 -> FREE | FJ27: 80
AA28: FREE | BF28: M02 | BU28: S10 | CF28: S12 | CU28: M13 | DZ28: FREE | EP28: FREE | FH28: XS12 | FI28: =AZ24 -> FREE | FJ28: 80
FH29: XS13 | FI29: =J60 -> FREE | FJ29: 80
BF30: FREE | BU30: FREE | CF30: FREE | CU30: FREE | FH30: XS14 | FI30: =BN11 -> FREE | FJ30: 80
FH31: XS15 | FI31: =T67 -> FREE | FJ31: 80
FH32: XS16 | FI32: =BN22 -> FREE | FJ32: 80
AY33: S05 | DB33: S14 | EX33: SOY1 | FH33: XS17 | FI33: =C101 -> FREE | FJ33: 80
S34: XS05 | BL34: S02 | EH34: XS37 | FH34: XS18 | FI34: =J94 -> FREE | FJ34: 80
B35: SOY4 | AY35: FREE | CN35: S04 | DB35: FREE | FH35: XS19 | FI35: =T91 -> FREE | FJ35: 80
S36: FREE | BL36: FREE | BZ36: L03 | EH36: FREE | FH36: XS20 | FI36: =CM22 -> FREE | FJ36: 80
CN37: FREE | FH37: XS21 | FI37: =CL11 -> FREE | FJ37: 80
BZ38: FREE | FH38: XS22 | FI38: =CZ5 -> FREE | FJ38: 80
FH39: XS23 | FI39: =R112 -> FREE | FJ39: 80
BF40: M05 | BS40: M07 | CU40: M17 | FH40: XS24 | FI40: =X106 -> FREE | FJ40: 80
Z41: XS10 | AQ41: L01 | CH41: M12 | DJ41: L07 | EA41: XS36 | FH41: XS25 | FI41: =DB23 -> FREE | FJ41: 80
...

Sheet Вторник 8
AG2: SOY3 | DS2: SOY2 | EM2: Для переноса данных с прошлого дня копируем таблицу в пределах границ Таблица сделана в штате 463 Союзом Carent Morte(CRT)
BB3: XS08 | BZ3: S06 | CZ3: XS22 | FG3: Союзы | FH3: Нефти по дняM недели заработали | FT3: ИТОГО | FY3: 2
FH4: Вторник 1 | FI4: Среда 2 | FJ4: Четверг 3 | FK4: Пятница 4 | FL4: Суббота 5 | FM4: Воскресенье 6 | FN4: Понедельник 7 | FO4: Вторник 8 | FP4: Среда 9 | FQ4: Четверг 10 | FR4: Пятница 11 | FS4: Суббота 12
BB5: FREE | BZ5: FREE | CZ5: FREE | FG5: SOY1 | FH5: ='Вторник 1'!FH5 -> 0 | FI5: ='Среда 2'!FI5 -> 0 | FJ5: ='Четверг 3'!FJ5 -> 0 | FK5: ='Пятница 4'!FK5 -> 0 | FL5: ='Суббота 5'!FL5 -> 0 | FM5: ='Воскресенье 6'!FM5 -> 0 | FN5: ='Понедельник 7'!FN5 -> 0 | FO5: =SUMIF($FI$17:$FI$181,FG5,$FJ$17:$FJ$181) -> 0 | FT5: =SUM(FH5:FS5) -> 0
FG6: SOY2 | FH6: ='Вторник 1'!FH6 -> 0 | FI6: ='Среда 2'!FI6 -> 0 | FJ6: ='Четверг 3'!FJ6 -> 0 | FK6: ='Пятница 4'!FK6 -> 0 | FL6: ='Суббота 5'!FL6 -> 0 | FM6: ='Воскресенье 6'!FM6 -> 0 | FN6: ='Понедельник 7'!FN6 -> 0 | FO6: =SUMIF($FI$17:$FI$181,FG6,$FJ$17:$FJ$181) -> 0 | FT6: =SUM(FH6:FS6) -> 0
FG7: SOY3 | FH7: ='Вторник 1'!FH7 -> 0 | FI7: ='Среда 2'!FI7 -> 0 | FJ7: ='Четверг 3'!FJ7 -> 0 | FK7: ='Пятница 4'!FK7 -> 0 | FL7: ='Суббота 5'!FL7 -> 0 | FM7: ='Воскресенье 6'!FM7 -> 0 | FN7: ='Понедельник 7'!FN7 -> 0 | FO7: =SUMIF($FI$17:$FI$181,FG7,$FJ$17:$FJ$181) -> 0 | FT7: =SUM(FH7:FS7) -> 0
FG8: SOY4 | FH8: ='Вторник 1'!FH8 -> 0 | FI8: ='Среда 2'!FI8 -> 0 | FJ8: ='Четверг 3'!FJ8 -> 0 | FK8: ='Пятница 4'!FK8 -> 0 | FL8: ='Суббота 5'!FL8 -> 0 | FM8: ='Воскресенье 6'!FM8 -> 0 | FN8: ='Понедельник 7'!FN8 -> 0 | FO8: =SUMIF($FI$17:$FI$181,FG8,$FJ$17:$FJ$181) -> 0 | FT8: =SUM(FH8:FS8) -> 0
BN9: XS14 | CL9: XS21 | FG9: SOY5 | FH9: ='Вторник 1'!FH9 -> 0 | FI9: ='Среда 2'!FI9 -> 0 | FJ9: ='Четверг 3'!FJ9 -> 0 | FK9: ='Пятница 4'!FK9 -> 0 | FL9: ='Суббота 5'!FL9 -> 0 | FM9: ='Воскресенье 6'!FM9 -> 0 | FN9: ='Понедельник 7'!FN9 -> 0 | FO9: =SUMIF($FI$17:$FI$181,FG9,$FJ$17:$FJ$181) -> 0 | FT9: =SUM(FH9:FS9) -> 0
Z10: XS02 | EA10: XS32 | FG10: SOY6 | FH10: ='Вторник 1'!FH10 -> 0 | FI10: ='Среда 2'!FI10 -> 0 | FJ10: ='Четверг 3'!FJ10 -> 0 | FK10: ='Пятница 4'!FK10 -> 0 | FL10: ='Суббота 5'!FL10 -> 0 | FM10: ='Воскресенье 6'!FM10 -> 0 | FN10: ='Понедельник 7'!FN10 -> 0 | FO10: =SUMIF($FI$17:$FI$181,FG10,$FJ$17:$FJ$181) -> 0 | FT10: =SUM(FH10:FS10) -> 0
BN11: FREE | BZ11: S08 | CL11: FREE | FG11: SOY7 | FH11: ='Вторник 1'!FH11 -> 0 | FI11: ='Среда 2'!FI11 -> 0 | FJ11: ='Четверг 3'!FJ11 -> 0 | FK11: ='Пятница 4'!FK11 -> 0 | FL11: ='Суббота 5'!FL11 -> 0 | FM11: ='Воскресенье 6'!FM11 -> 0 | FN11: ='Понедельник 7'!FN11 -> 0 | FO11: =SUMIF($FI$17:$FI$181,FG11,$FJ$17:$FJ$181) -> 0 | FT11: =SUM(FH11:FS11) -> 0
Z12: FREE | EA12: FREE | FG12: SOY8 | FH12: ='Вторник 1'!FH12 -> 0 | FI12: ='Среда 2'!FI12 -> 0 | FJ12: ='Четверг 3'!FJ12 -> 0 | FK12: ='Пятница 4'!FK12 -> 0 | FL12: ='Суббота 5'!FL12 -> 0 | FM12: ='Воскресенье 6'!FM12 -> 0 | FN12: ='Понедельник 7'!FN12 -> 0 | FO12: =SUMIF($FI$17:$FI$181,FG12,$FJ$17:$FJ$181) -> 0 | FT12: =SUM(FH12:FS12) -> 0
BZ13: FREE | DI13: XS26 | FG13: FREE
AS14: XS07
DI15: FREE | FG15: Точка добычи | FI15: Cоюз | FJ15: Дают очков
AS16: FREE
FG17: ЛОГОВА | FH17: XS01 | FI17: =K27 -> FREE | FJ17: 80
S18: S01 | AI18: XS06 | EH18: S18 | FH18: XS02 | FI18: =Z12 -> FREE | FJ18: 80
DS19: XS31 | FH19: XS03 | FI19: =C52 -> FREE | FJ19: 80
S20: FREE | AI20: FREE | BN20: XS16 | CM20: XS20 | EH20: FREE | FH20: XS04 | FI20: =O44 -> FREE | FJ20: 80
DB21: XS25 | DS21: FREE | FH21: XS05 | FI21: =S36 -> FREE | FJ21: 80
AZ22: XS12 | BN22: FREE | CM22: FREE | FH22: XS06 | FI22: =AI20 -> FREE | FJ22: 80
DB23: FREE | FH23: XS07 | FI23: =AS16 -> FREE | FJ23: 80
AZ24: FREE | FH24: XS08 | FI24: =BB5 -> FREE | FJ24: 80
K25: XS01 | AQ25: XS11 | DK25: XS30 | FH25: XS09 | FI25: =V51 -> FREE | FJ25: 80
AA26: S02 | DZ26: S17 | EP26: XS38 | FH26: XS10 | FI26: =Z43 -> FREE | FJ26: 80
K27: FREE | AQ27: FREE | DK27: FREE | FH27: XS11 | FI27: =AQ27 -> FREE | FJ27: 80
AA28: FREE | BF28: M02 | BU28: S10 | CF28: S12 | CU28: M13 | DZ28: FREE | EP28: FREE | FH28: XS12 | FI28: =AZ24 -> FREE | FJ28: 80
FH29: XS13 | FI29: =J60 -> FREE | FJ29: 80
BF30: FREE | BU30: FREE | CF30: FREE | CU30: FREE | FH30: XS14 | FI30: =BN11 -> FREE | FJ30: 80
FH31: XS15 | FI31: =T67 -> FREE | FJ31: 80
FH32: XS16 | FI32: =BN22 -> FREE | FJ32: 80
AY33: S05 | DB33: S14 | EX33: SOY1 | FH33: XS17 | FI33: =C101 -> FREE | FJ33: 80
S34: XS05 | BL34: S02 | EH34: XS37 | FH34: XS18 | FI34: =J94 -> FREE | FJ34: 80
B35: SOY4 | AY35: FREE | CN35: S04 | DB35: FREE | FH35: XS19 | FI35: =T91 -> FREE | FJ35: 80
S36: FREE | BL36: FREE | BZ36: L03 | EH36: FREE | FH36: XS20 | FI36: =CM22 -> FREE | FJ36: 80
CN37: FREE | FH37: XS21 | FI37: =CL11 -> FREE | FJ37: 80
BZ38: FREE | FH38: XS22 | FI38: =CZ5 -> FREE | FJ38: 80
FH39: XS23 | FI39: =R112 -> FREE | FJ39: 80
BF40: M05 | BS40: M07 | CU40: M17 | FH40: XS24 | FI40: =X106 -> FREE | FJ40: 80
Z41: XS10 | AQ41: L01 | CH41: M12 | DJ41: L07 | EA41: XS36 | FH41: XS25 | FI41: =DB23 -> FREE | FJ41: 80
...

Sheet Среда 9
AG2: SOY3 | DS2: SOY2 | EM2: Для переноса данных с прошлого дня копируем таблицу в пределах границ Таблица сделана в штате 463 Союзом Carent Morte(CRT)
BB3: XS08 | BZ3: S06 | CZ3: XS22 | FG3: Союзы | FH3: Нефти по дняM недели заработали | FT3: ИТОГО | FY3: 2
FH4: Вторник 1 | FI4: Среда 2 | FJ4: Четверг 3 | FK4: Пятница 4 | FL4: Суббота 5 | FM4: Воскресенье 6 | FN4: Понедельник 7 | FO4: Вторник 8 | FP4: Среда 9 | FQ4: Четверг 10 | FR4: Пятница 11 | FS4: Суббота 12
BB5: FREE | BZ5: FREE | CZ5: FREE | FG5: SOY1 | FH5: ='Вторник 1'!FH5 -> 0 | FI5: ='Среда 2'!FI5 -> 0 | FJ5: ='Четверг 3'!FJ5 -> 0 | FK5: ='Пятница 4'!FK5 -> 0 | FL5: ='Суббота 5'!FL5 -> 0 | FM5: ='Воскресенье 6'!FM5 -> 0 | FN5: ='Понедельник 7'!FN5 -> 0 | FO5: ='Вторник 8'!FO5 -> 0 | FP5: =SUMIF($FI$17:$FI$181,FG5,$FJ$17:$FJ$181) -> 0 | FT5: =SUM(FH5:FS5) -> 0
FG6: SOY2 | FH6: ='Вторник 1'!FH6 -> 0 | FI6: ='Среда 2'!FI6 -> 0 | FJ6: ='Четверг 3'!FJ6 -> 0 | FK6: ='Пятница 4'!FK6 -> 0 | FL6: ='Суббота 5'!FL6 -> 0 | FM6: ='Воскресенье 6'!FM6 -> 0 | FN6: ='Понедельник 7'!FN6 -> 0 | FO6: ='Вторник 8'!FO6 -> 0 | FP6: =SUMIF($FI$17:$FI$181,FG6,$FJ$17:$FJ$181) -> 0 | FT6: =SUM(FH6:FS6) -> 0
FG7: SOY3 | FH7: ='Вторник 1'!FH7 -> 0 | FI7: ='Среда 2'!FI7 -> 0 | FJ7: ='Четверг 3'!FJ7 -> 0 | FK7: ='Пятница 4'!FK7 -> 0 | FL7: ='Суббота 5'!FL7 -> 0 | FM7: ='Воскресенье 6'!FM7 -> 0 | FN7: ='Понедельник 7'!FN7 -> 0 | FO7: ='Вторник 8'!FO7 -> 0 | FP7: =SUMIF($FI$17:$FI$181,FG7,$FJ$17:$FJ$181) -> 0 | FT7: =SUM(FH7:FS7) -> 0
FG8: SOY4 | FH8: ='Вторник 1'!FH8 -> 0 | FI8: ='Среда 2'!FI8 -> 0 | FJ8: ='Четверг 3'!FJ8 -> 0 | FK8: ='Пятница 4'!FK8 -> 0 | FL8: ='Суббота 5'!FL8 -> 0 | FM8: ='Воскресенье 6'!FM8 -> 0 | FN8: ='Понедельник 7'!FN8 -> 0 | FO8: ='Вторник 8'!FO8 -> 0 | FP8: =SUMIF($FI$17:$FI$181,FG8,$FJ$17:$FJ$181) -> 0 | FT8: =SUM(FH8:FS8) -> 0
BN9: XS14 | CL9: XS21 | FG9: SOY5 | FH9: ='Вторник 1'!FH9 -> 0 | FI9: ='Среда 2'!FI9 -> 0 | FJ9: ='Четверг 3'!FJ9 -> 0 | FK9: ='Пятница 4'!FK9 -> 0 | FL9: ='Суббота 5'!FL9 -> 0 | FM9: ='Воскресенье 6'!FM9 -> 0 | FN9: ='Понедельник 7'!FN9 -> 0 | FO9: ='Вторник 8'!FO9 -> 0 | FP9: =SUMIF($FI$17:$FI$181,FG9,$FJ$17:$FJ$181) -> 0 | FT9: =SUM(FH9:FS9) -> 0
Z10: XS02 | EA10: XS32 | FG10: SOY6 | FH10: ='Вторник 1'!FH10 -> 0 | FI10: ='Среда 2'!FI10 -> 0 | FJ10: ='Четверг 3'!FJ10 -> 0 | FK10: ='Пятница 4'!FK10 -> 0 | FL10: ='Суббота 5'!FL10 -> 0 | FM10: ='Воскресенье 6'!FM10 -> 0 | FN10: ='Понедельник 7'!FN10 -> 0 | FO10: ='Вторник 8'!FO10 -> 0 | FP10: =SUMIF($FI$17:$FI$181,FG10,$FJ$17:$FJ$181) -> 0 | FT10: =SUM(FH10:FS10) -> 0
BN11: FREE | BZ11: S08 | CL11: FREE | FG11: SOY7 | FH11: ='Вторник 1'!FH11 -> 0 | FI11: ='Среда 2'!FI11 -> 0 | FJ11: ='Четверг 3'!FJ11 -> 0 | FK11: ='Пятница 4'!FK11 -> 0 | FL11: ='Суббота 5'!FL11 -> 0 | FM11: ='Воскресенье 6'!FM11 -> 0 | FN11: ='Понедельник 7'!FN11 -> 0 | FO11: ='Вторник 8'!FO11 -> 0 | FP11: =SUMIF($FI$17:$FI$181,FG11,$FJ$17:$FJ$181) -> 0 | FT11: =SUM(FH11:FS11) -> 0
Z12: FREE | EA12: FREE | FG12: SOY8 | FH12: ='Вторник 1'!FH12 -> 0 | FI12: ='Среда 2'!FI12 -> 0 | FJ12: ='Четверг 3'!FJ12 -> 0 | FK12: ='Пятница 4'!FK12 -> 0 | FL12: ='Суббота 5'!FL12 -> 0 | FM12: ='Воскресенье 6'!FM12 -> 0 | FN12: ='Понедельник 7'!FN12 -> 0 | FO12: ='Вторник 8'!FO12 -> 0 | FP12: =SUMIF($FI$17:$FI$181,FG12,$FJ$17:$FJ$181) -> 0 | FT12: =SUM(FH12:FS12) -> 0
BZ13: FREE | DI13: XS26 | FG13: FREE
AS14: XS07
DI15: FREE | FG15: Точка добычи | FI15: Cоюз | FJ15: Дают очков
AS16: FREE
FG17: ЛОГОВА | FH17: XS01 | FI17: =K27 -> FREE | FJ17: 80
S18: S01 | AI18: XS06 | EH18: S18 | FH18: XS02 | FI18: =Z12 -> FREE | FJ18: 80
DS19: XS31 | FH19: XS03 | FI19: =C52 -> FREE | FJ19: 80
S20: FREE | AI20: FREE | BN20: XS16 | CM20: XS20 | EH20: FREE | FH20: XS04 | FI20: =O44 -> FREE | FJ20: 80
DB21: XS25 | DS21: FREE | FH21: XS05 | FI21: =S36 -> FREE | FJ21: 80
AZ22: XS12 | BN22: FREE | CM22: FREE | FH22: XS06 | FI22: =AI20 -> FREE | FJ22: 80
DB23: FREE | FH23: XS07 | FI23: =AS16 -> FREE | FJ23: 80
AZ24: FREE | FH24: XS08 | FI24: =BB5 -> FREE | FJ24: 80
K25: XS01 | AQ25: XS11 | DK25: XS30 | FH25: XS09 | FI25: =V51 -> FREE | FJ25: 80
AA26: S02 | DZ26: S17 | EP26: XS38 | FH26: XS10 | FI26: =Z43 -> FREE | FJ26: 80
K27: FREE | AQ27: FREE | DK27: FREE | FH27: XS11 | FI27: =AQ27 -> FREE | FJ27: 80
AA28: FREE | BF28: M02 | BU28: S10 | CF28: S12 | CU28: M13 | DZ28: FREE | EP28: FREE | FH28: XS12 | FI28: =AZ24 -> FREE | FJ28: 80
FH29: XS13 | FI29: =J60 -> FREE | FJ29: 80
BF30: FREE | BU30: FREE | CF30: FREE | CU30: FREE | FH30: XS14 | FI30: =BN11 -> FREE | FJ30: 80
FH31: XS15 | FI31: =T67 -> FREE | FJ31: 80
FH32: XS16 | FI32: =BN22 -> FREE | FJ32: 80
AY33: S05 | DB33: S14 | EX33: SOY1 | FH33: XS17 | FI33: =C101 -> FREE | FJ33: 80
S34: XS05 | BL34: S02 | EH34: XS37 | FH34: XS18 | FI34: =J94 -> FREE | FJ34: 80
B35: SOY4 | AY35: FREE | CN35: S04 | DB35: FREE | FH35: XS19 | FI35: =T91 -> FREE | FJ35: 80
S36: FREE | BL36: FREE | BZ36: L03 | EH36: FREE | FH36: XS20 | FI36: =CM22 -> FREE | FJ36: 80
CN37: FREE | FH37: XS21 | FI37: =CL11 -> FREE | FJ37: 80
BZ38: FREE | FH38: XS22 | FI38: =CZ5 -> FREE | FJ38: 80
FH39: XS23 | FI39: =R112 -> FREE | FJ39: 80
BF40: M05 | BS40: M07 | CU40: M17 | FH40: XS24 | FI40: =X106 -> FREE | FJ40: 80
Z41: XS10 | AQ41: L01 | CH41: M12 | DJ41: L07 | EA41: XS36 | FH41: XS25 | FI41: =DB23 -> FREE | FJ41: 80
...

Sheet Четверг 10
AG2: SOY3 | DS2: SOY2 | EM2: Для переноса данных с прошлого дня копируем таблицу в пределах границ Таблица сделана в штате 463 Союзом Carent Morte(CRT)
BB3: XS08 | BZ3: S06 | CZ3: XS22 | FG3: Союзы | FH3: Нефти по дняM недели заработали | FT3: ИТОГО | FY3: 2
FH4: Вторник 1 | FI4: Среда 2 | FJ4: Четверг 3 | FK4: Пятница 4 | FL4: Суббота 5 | FM4: Воскресенье 6 | FN4: Понедельник 7 | FO4: Вторник 8 | FP4: Среда 9 | FQ4: Четверг 10 | FR4: Пятница 11 | FS4: Суббота 12
BB5: FREE | BZ5: FREE | CZ5: FREE | FG5: SOY1 | FH5: ='Вторник 1'!FH5 -> 0 | FI5: ='Среда 2'!FI5 -> 0 | FJ5: ='Четверг 3'!FJ5 -> 0 | FK5: ='Пятница 4'!FK5 -> 0 | FL5: ='Суббота 5'!FL5 -> 0 | FM5: ='Воскресенье 6'!FM5 -> 0 | FN5: ='Понедельник 7'!FN5 -> 0 | FO5: ='Вторник 8'!FO5 -> 0 | FP5: ='Среда 9'!FP5 -> 0 | FQ5: =SUMIF($FI$17:$FI$181,FG5,$FJ$17:$FJ$181) -> 0 | FT5: =SUM(FH5:FS5) -> 0
FG6: SOY2 | FH6: ='Вторник 1'!FH6 -> 0 | FI6: ='Среда 2'!FI6 -> 0 | FJ6: ='Четверг 3'!FJ6 -> 0 | FK6: ='Пятница 4'!FK6 -> 0 | FL6: ='Суббота 5'!FL6 -> 0 | FM6: ='Воскресенье 6'!FM6 -> 0 | FN6: ='Понедельник 7'!FN6 -> 0 | FO6: ='Вторник 8'!FO6 -> 0 | FP6: ='Среда 9'!FP6 -> 0 | FQ6: =SUMIF($FI$17:$FI$181,FG6,$FJ$17:$FJ$181) -> 0 | FT6: =SUM(FH6:FS6) -> 0
FG7: SOY3 | FH7: ='Вторник 1'!FH7 -> 0 | FI7: ='Среда 2'!FI7 -> 0 | FJ7: ='Четверг 3'!FJ7 -> 0 | FK7: ='Пятница 4'!FK7 -> 0 | FL7: ='Суббота 5'!FL7 -> 0 | FM7: ='Воскресенье 6'!FM7 -> 0 | FN7: ='Понедельник 7'!FN7 -> 0 | FO7: ='Вторник 8'!FO7 -> 0 | FP7: ='Среда 9'!FP7 -> 0 | FQ7: =SUMIF($FI$17:$FI$181,FG7,$FJ$17:$FJ$181) -> 0 | FT7: =SUM(FH7:FS7) -> 0
FG8: SOY4 | FH8: ='Вторник 1'!FH8 -> 0 | FI8: ='Среда 2'!FI8 -> 0 | FJ8: ='Четверг 3'!FJ8 -> 0 | FK8: ='Пятница 4'!FK8 -> 0 | FL8: ='Суббота 5'!FL8 -> 0 | FM8: ='Воскресенье 6'!FM8 -> 0 | FN8: ='Понедельник 7'!FN8 -> 0 | FO8: ='Вторник 8'!FO8 -> 0 | FP8: ='Среда 9'!FP8 -> 0 | FQ8: =SUMIF($FI$17:$FI$181,FG8,$FJ$17:$FJ$181) -> 0 | FT8: =SUM(FH8:FS8) -> 0
BN9: XS14 | CL9: XS21 | FG9: SOY5 | FH9: ='Вторник 1'!FH9 -> 0 | FI9: ='Среда 2'!FI9 -> 0 | FJ9: ='Четверг 3'!FJ9 -> 0 | FK9: ='Пятница 4'!FK9 -> 0 | FL9: ='Суббота 5'!FL9 -> 0 | FM9: ='Воскресенье 6'!FM9 -> 0 | FN9: ='Понедельник 7'!FN9 -> 0 | FO9: ='Вторник 8'!FO9 -> 0 | FP9: ='Среда 9'!FP9 -> 0 | FQ9: =SUMIF($FI$17:$FI$181,FG9,$FJ$17:$FJ$181) -> 0 | FT9: =SUM(FH9:FS9) -> 0
Z10: XS02 | EA10: XS32 | FG10: SOY6 | FH10: ='Вторник 1'!FH10 -> 0 | FI10: ='Среда 2'!FI10 -> 0 | FJ10: ='Четверг 3'!FJ10 -> 0 | FK10: ='Пятница 4'!FK10 -> 0 | FL10: ='Суббота 5'!FL10 -> 0 | FM10: ='Воскресенье 6'!FM10 -> 0 | FN10: ='Понедельник 7'!FN10 -> 0 | FO10: ='Вторник 8'!FO10 -> 0 | FP10: ='Среда 9'!FP10 -> 0 | FQ10: =SUMIF($FI$17:$FI$181,FG10,$FJ$17:$FJ$181) -> 0 | FT10: =SUM(FH10:FS10) -> 0
BN11: FREE | BZ11: S08 | CL11: FREE | FG11: SOY7 | FH11: ='Вторник 1'!FH11 -> 0 | FI11: ='Среда 2'!FI11 -> 0 | FJ11: ='Четверг 3'!FJ11 -> 0 | FK11: ='Пятница 4'!FK11 -> 0 | FL11: ='Суббота 5'!FL11 -> 0 | FM11: ='Воскресенье 6'!FM11 -> 0 | FN11: ='Понедельник 7'!FN11 -> 0 | FO11: ='Вторник 8'!FO11 -> 0 | FP11: ='Среда 9'!FP11 -> 0 | FQ11: =SUMIF($FI$17:$FI$181,FG11,$FJ$17:$FJ$181) -> 0 | FT11: =SUM(FH11:FS11) -> 0
Z12: FREE | EA12: FREE | FG12: SOY8 | FH12: ='Вторник 1'!FH12 -> 0 | FI12: ='Среда 2'!FI12 -> 0 | FJ12: ='Четверг 3'!FJ12 -> 0 | FK12: ='Пятница 4'!FK12 -> 0 | FL12: ='Суббота 5'!FL12 -> 0 | FM12: ='Воскресенье 6'!FM12 -> 0 | FN12: ='Понедельник 7'!FN12 -> 0 | FO12: ='Вторник 8'!FO12 -> 0 | FP12: ='Среда 9'!FP12 -> 0 | FQ12: =SUMIF($FI$17:$FI$181,FG12,$FJ$17:$FJ$181) -> 0 | FT12: =SUM(FH12:FS12) -> 0
BZ13: FREE | DI13: XS26 | FG13: FREE
AS14: XS07
DI15: FREE | FG15: Точка добычи | FI15: Cоюз | FJ15: Дают очков
AS16: FREE
FG17: ЛОГОВА | FH17: XS01 | FI17: =K27 -> FREE | FJ17: 80
S18: S01 | AI18: XS06 | EH18: S18 | FH18: XS02 | FI18: =Z12 -> FREE | FJ18: 80
DS19: XS31 | FH19: XS03 | FI19: =C52 -> FREE | FJ19: 80
S20: FREE | AI20: FREE | BN20: XS16 | CM20: XS20 | EH20: FREE | FH20: XS04 | FI20: =O44 -> FREE | FJ20: 80
DB21: XS25 | DS21: FREE | FH21: XS05 | FI21: =S36 -> FREE | FJ21: 80
AZ22: XS12 | BN22: FREE | CM22: FREE | FH22: XS06 | FI22: =AI20 -> FREE | FJ22: 80
DB23: FREE | FH23: XS07 | FI23: =AS16 -> FREE | FJ23: 80
AZ24: FREE | FH24: XS08 | FI24: =BB5 -> FREE | FJ24: 80
K25: XS01 | AQ25: XS11 | DK25: XS30 | FH25: XS09 | FI25: =V51 -> FREE | FJ25: 80
AA26: S02 | DZ26: S17 | EP26: XS38 | FH26: XS10 | FI26: =Z43 -> FREE | FJ26: 80
K27: FREE | AQ27: FREE | DK27: FREE | FH27: XS11 | FI27: =AQ27 -> FREE | FJ27: 80
AA28: FREE | BF28: M02 | BU28: S10 | CF28: S12 | CU28: M13 | DZ28: FREE | EP28: FREE | FH28: XS12 | FI28: =AZ24 -> FREE | FJ28: 80
FH29: XS13 | FI29: =J60 -> FREE | FJ29: 80
BF30: FREE | BU30: FREE | CF30: FREE | CU30: FREE | FH30: XS14 | FI30: =BN11 -> FREE | FJ30: 80
FH31: XS15 | FI31: =T67 -> FREE | FJ31: 80
FH32: XS16 | FI32: =BN22 -> FREE | FJ32: 80
AY33: S05 | DB33: S14 | EX33: SOY1 | FH33: XS17 | FI33: =C101 -> FREE | FJ33: 80
S34: XS05 | BL34: S02 | EH34: XS37 | FH34: XS18 | FI34: =J94 -> FREE | FJ34: 80
B35: SOY4 | AY35: FREE | CN35: S04 | DB35: FREE | FH35: XS19 | FI35: =T91 -> FREE | FJ35: 80
S36: FREE | BL36: FREE | BZ36: L03 | EH36: FREE | FH36: XS20 | FI36: =CM22 -> FREE | FJ36: 80
CN37: FREE | FH37: XS21 | FI37: =CL11 -> FREE | FJ37: 80
BZ38: FREE | FH38: XS22 | FI38: =CZ5 -> FREE | FJ38: 80
FH39: XS23 | FI39: =R112 -> FREE | FJ39: 80
BF40: M05 | BS40: M07 | CU40: M17 | FH40: XS24 | FI40: =X106 -> FREE | FJ40: 80
Z41: XS10 | AQ41: L01 | CH41: M12 | DJ41: L07 | EA41: XS36 | FH41: XS25 | FI41: =DB23 -> FREE | FJ41: 80
...

Sheet Пятница 11
AG2: SOY3 | DS2: SOY2 | EM2: Для переноса данных с прошлого дня копируем таблицу в пределах границ Таблица сделана в штате 463 Союзом Carent Morte(CRT)
BB3: XS08 | BZ3: S06 | CZ3: XS22 | FG3: Союзы | FH3: Нефти по дняM недели заработали | FT3: ИТОГО | FY3: 2
FH4: Вторник 1 | FI4: Среда 2 | FJ4: Четверг 3 | FK4: Пятница 4 | FL4: Суббота 5 | FM4: Воскресенье 6 | FN4: Понедельник 7 | FO4: Вторник 8 | FP4: Среда 9 | FQ4: Четверг 10 | FR4: Пятница 11 | FS4: Суббота 12
BB5: FREE | BZ5: FREE | CZ5: FREE | FG5: SOY1 | FH5: ='Вторник 1'!FH5 -> 0 | FI5: ='Среда 2'!FI5 -> 0 | FJ5: ='Четверг 3'!FJ5 -> 0 | FK5: ='Пятница 4'!FK5 -> 0 | FL5: ='Суббота 5'!FL5 -> 0 | FM5: ='Воскресенье 6'!FM5 -> 0 | FN5: ='Понедельник 7'!FN5 -> 0 | FO5: ='Вторник 8'!FO5 -> 0 | FP5: ='Среда 9'!FP5 -> 0 | FQ5: ='Четверг 10'!FQ5 -> 0 | FR5: =SUMIF($FI$17:$FI$181,FG5,$FJ$17:$FJ$181) -> 0 | FT5: =SUM(FH5:FS5) -> 0
FG6: SOY2 | FH6: ='Вторник 1'!FH6 -> 0 | FI6: ='Среда 2'!FI6 -> 0 | FJ6: ='Четверг 3'!FJ6 -> 0 | FK6: ='Пятница 4'!FK6 -> 0 | FL6: ='Суббота 5'!FL6 -> 0 | FM6: ='Воскресенье 6'!FM6 -> 0 | FN6: ='Понедельник 7'!FN6 -> 0 | FO6: ='Вторник 8'!FO6 -> 0 | FP6: ='Среда 9'!FP6 -> 0 | FQ6: ='Четверг 10'!FQ6 -> 0 | FR6: =SUMIF($FI$17:$FI$181,FG6,$FJ$17:$FJ$181) -> 0 | FT6: =SUM(FH6:FS6) -> 0
FG7: SOY3 | FH7: ='Вторник 1'!FH7 -> 0 | FI7: ='Среда 2'!FI7 -> 0 | FJ7: ='Четверг 3'!FJ7 -> 0 | FK7: ='Пятница 4'!FK7 -> 0 | FL7: ='Суббота 5'!FL7 -> 0 | FM7: ='Воскресенье 6'!FM7 -> 0 | FN7: ='Понедельник 7'!FN7 -> 0 | FO7: ='Вторник 8'!FO7 -> 0 | FP7: ='Среда 9'!FP7 -> 0 | FQ7: ='Четверг 10'!FQ7 -> 0 | FR7: =SUMIF($FI$17:$FI$181,FG7,$FJ$17:$FJ$181) -> 0 | FT7: =SUM(FH7:FS7) -> 0
FG8: SOY4 | FH8: ='Вторник 1'!FH8 -> 0 | FI8: ='Среда 2'!FI8 -> 0 | FJ8: ='Четверг 3'!FJ8 -> 0 | FK8: ='Пятница 4'!FK8 -> 0 | FL8: ='Суббота 5'!FL8 -> 0 | FM8: ='Воскресенье 6'!FM8 -> 0 | FN8: ='Понедельник 7'!FN8 -> 0 | FO8: ='Вторник 8'!FO8 -> 0 | FP8: ='Среда 9'!FP8 -> 0 | FQ8: ='Четверг 10'!FQ8 -> 0 | FR8: =SUMIF($FI$17:$FI$181,FG8,$FJ$17:$FJ$181) -> 0 | FT8: =SUM(FH8:FS8) -> 0
BN9: XS14 | CL9: XS21 | FG9: SOY5 | FH9: ='Вторник 1'!FH9 -> 0 | FI9: ='Среда 2'!FI9 -> 0 | FJ9: ='Четверг 3'!FJ9 -> 0 | FK9: ='Пятница 4'!FK9 -> 0 | FL9: ='Суббота 5'!FL9 -> 0 | FM9: ='Воскресенье 6'!FM9 -> 0 | FN9: ='Понедельник 7'!FN9 -> 0 | FO9: ='Вторник 8'!FO9 -> 0 | FP9: ='Среда 9'!FP9 -> 0 | FQ9: ='Четверг 10'!FQ9 -> 0 | FR9: =SUMIF($FI$17:$FI$181,FG9,$FJ$17:$FJ$181) -> 0 | FT9: =SUM(FH9:FS9) -> 0
Z10: XS02 | EA10: XS32 | FG10: SOY6 | FH10: ='Вторник 1'!FH10 -> 0 | FI10: ='Среда 2'!FI10 -> 0 | FJ10: ='Четверг 3'!FJ10 -> 0 | FK10: ='Пятница 4'!FK10 -> 0 | FL10: ='Суббота 5'!FL10 -> 0 | FM10: ='Воскресенье 6'!FM10 -> 0 | FN10: ='Понедельник 7'!FN10 -> 0 | FO10: ='Вторник 8'!FO10 -> 0 | FP10: ='Среда 9'!FP10 -> 0 | FQ10: ='Четверг 10'!FQ10 -> 0 | FR10: =SUMIF($FI$17:$FI$181,FG10,$FJ$17:$FJ$181) -> 0 | FT10: =SUM(FH10:FS10) -> 0
BN11: FREE | BZ11: S08 | CL11: FREE | FG11: SOY7 | FH11: ='Вторник 1'!FH11 -> 0 | FI11: ='Среда 2'!FI11 -> 0 | FJ11: ='Четверг 3'!FJ11 -> 0 | FK11: ='Пятница 4'!FK11 -> 0 | FL11: ='Суббота 5'!FL11 -> 0 | FM11: ='Воскресенье 6'!FM11 -> 0 | FN11: ='Понедельник 7'!FN11 -> 0 | FO11: ='Вторник 8'!FO11 -> 0 | FP11: ='Среда 9'!FP11 -> 0 | FQ11: ='Четверг 10'!FQ11 -> 0 | FR11: =SUMIF($FI$17:$FI$181,FG11,$FJ$17:$FJ$181) -> 0 | FT11: =SUM(FH11:FS11) -> 0
Z12: FREE | EA12: FREE | FG12: SOY8 | FH12: ='Вторник 1'!FH12 -> 0 | FI12: ='Среда 2'!FI12 -> 0 | FJ12: ='Четверг 3'!FJ12 -> 0 | FK12: ='Пятница 4'!FK12 -> 0 | FL12: ='Суббота 5'!FL12 -> 0 | FM12: ='Воскресенье 6'!FM12 -> 0 | FN12: ='Понедельник 7'!FN12 -> 0 | FO12: ='Вторник 8'!FO12 -> 0 | FP12: ='Среда 9'!FP12 -> 0 | FQ12: ='Четверг 10'!FQ12 -> 0 | FR12: =SUMIF($FI$17:$FI$181,FG12,$FJ$17:$FJ$181) -> 0 | FT12: =SUM(FH12:FS12) -> 0
BZ13: FREE | DI13: XS26 | FG13: FREE
AS14: XS07
DI15: FREE | FG15: Точка добычи | FI15: Cоюз | FJ15: Дают очков
AS16: FREE
FG17: ЛОГОВА | FH17: XS01 | FI17: =K27 -> FREE | FJ17: 80
S18: S01 | AI18: XS06 | EH18: S18 | FH18: XS02 | FI18: =Z12 -> FREE | FJ18: 80
DS19: XS31 | FH19: XS03 | FI19: =C52 -> FREE | FJ19: 80
S20: FREE | AI20: FREE | BN20: XS16 | CM20: XS20 | EH20: FREE | FH20: XS04 | FI20: =O44 -> FREE | FJ20: 80
DB21: XS25 | DS21: FREE | FH21: XS05 | FI21: =S36 -> FREE | FJ21: 80
AZ22: XS12 | BN22: FREE | CM22: FREE | FH22: XS06 | FI22: =AI20 -> FREE | FJ22: 80
DB23: FREE | FH23: XS07 | FI23: =AS16 -> FREE | FJ23: 80
AZ24: FREE | FH24: XS08 | FI24: =BB5 -> FREE | FJ24: 80
K25: XS01 | AQ25: XS11 | DK25: XS30 | FH25: XS09 | FI25: =V51 -> FREE | FJ25: 80
AA26: S02 | DZ26: S17 | EP26: XS38 | FH26: XS10 | FI26: =Z43 -> FREE | FJ26: 80
K27: FREE | AQ27: FREE | DK27: FREE | FH27: XS11 | FI27: =AQ27 -> FREE | FJ27: 80
AA28: FREE | BF28: M02 | BU28: S10 | CF28: S12 | CU28: M13 | DZ28: FREE | EP28: FREE | FH28: XS12 | FI28: =AZ24 -> FREE | FJ28: 80
FH29: XS13 | FI29: =J60 -> FREE | FJ29: 80
BF30: FREE | BU30: FREE | CF30: FREE | CU30: FREE | FH30: XS14 | FI30: =BN11 -> FREE | FJ30: 80
FH31: XS15 | FI31: =T67 -> FREE | FJ31: 80
FH32: XS16 | FI32: =BN22 -> FREE | FJ32: 80
AY33: S05 | DB33: S14 | EX33: SOY1 | FH33: XS17 | FI33: =C101 -> FREE | FJ33: 80
S34: XS05 | BL34: S02 | EH34: XS37 | FH34: XS18 | FI34: =J94 -> FREE | FJ34: 80
B35: SOY4 | AY35: FREE | CN35: S04 | DB35: FREE | FH35: XS19 | FI35: =T91 -> FREE | FJ35: 80
S36: FREE | BL36: FREE | BZ36: L03 | EH36: FREE | FH36: XS20 | FI36: =CM22 -> FREE | FJ36: 80
CN37: FREE | FH37: XS21 | FI37: =CL11 -> FREE | FJ37: 80
BZ38: FREE | FH38: XS22 | FI38: =CZ5 -> FREE | FJ38: 80
FH39: XS23 | FI39: =R112 -> FREE | FJ39: 80
BF40: M05 | BS40: M07 | CU40: M17 | FH40: XS24 | FI40: =X106 -> FREE | FJ40: 80
Z41: XS10 | AQ41: L01 | CH41: M12 | DJ41: L07 | EA41: XS36 | FH41: XS25 | FI41: =DB23 -> FREE | FJ41: 80
...

Sheet Суббота 12
AG2: SOY3 | DS2: SOY2 | EM2: Для переноса данных с прошлого дня копируем таблицу в пределах границ Таблица сделана в штате 463 Союзом Carent Morte(CRT)
BB3: XS08 | BZ3: S06 | CZ3: XS22 | FG3: Союзы | FH3: Нефти по дняM недели заработали | FT3: ИТОГО | FY3: 2
FH4: Вторник 1 | FI4: Среда 2 | FJ4: Четверг 3 | FK4: Пятница 4 | FL4: Суббота 5 | FM4: Воскресенье 6 | FN4: Понедельник 7 | FO4: Вторник 8 | FP4: Среда 9 | FQ4: Четверг 10 | FR4: Пятница 11 | FS4: Суббота 12
BB5: FREE | BZ5: FREE | CZ5: FREE | FG5: SOY1 | FH5: ='Вторник 1'!FH5 -> 0 | FI5: ='Среда 2'!FI5 -> 0 | FJ5: ='Четверг 3'!FJ5 -> 0 | FK5: ='Пятница 4'!FK5 -> 0 | FL5: ='Суббота 5'!FL5 -> 0 | FM5: ='Воскресенье 6'!FM5 -> 0 | FN5: ='Понедельник 7'!FN5 -> 0 | FO5: ='Вторник 8'!FO5 -> 0 | FP5: ='Среда 9'!FP5 -> 0 | FQ5: ='Четверг 10'!FQ5 -> 0 | FR5: ='Пятница 11'!FR5 -> 0 | FS5: =SUMIF($FI$17:$FI$181,FG5,$FJ$17:$FJ$181) -> 0 | FT5: =SUM(FH5:FS5) -> 0
FG6: SOY2 | FH6: ='Вторник 1'!FH6 -> 0 | FI6: ='Среда 2'!FI6 -> 0 | FJ6: ='Четверг 3'!FJ6 -> 0 | FK6: ='Пятница 4'!FK6 -> 0 | FL6: ='Суббота 5'!FL6 -> 0 | FM6: ='Воскресенье 6'!FM6 -> 0 | FN6: ='Понедельник 7'!FN6 -> 0 | FO6: ='Вторник 8'!FO6 -> 0 | FP6: ='Среда 9'!FP6 -> 0 | FQ6: ='Четверг 10'!FQ6 -> 0 | FR6: ='Пятница 11'!FR6 -> 0 | FS6: =SUMIF($FI$17:$FI$181,FG6,$FJ$17:$FJ$181) -> 0 | FT6: =SUM(FH6:FS6) -> 0
FG7: SOY3 | FH7: ='Вторник 1'!FH7 -> 0 | FI7: ='Среда 2'!FI7 -> 0 | FJ7: ='Четверг 3'!FJ7 -> 0 | FK7: ='Пятница 4'!FK7 -> 0 | FL7: ='Суббота 5'!FL7 -> 0 | FM7: ='Воскресенье 6'!FM7 -> 0 | FN7: ='Понедельник 7'!FN7 -> 0 | FO7: ='Вторник 8'!FO7 -> 0 | FP7: ='Среда 9'!FP7 -> 0 | FQ7: ='Четверг 10'!FQ7 -> 0 | FR7: ='Пятница 11'!FR7 -> 0 | FS7: =SUMIF($FI$17:$FI$181,FG7,$FJ$17:$FJ$181) -> 0 | FT7: =SUM(FH7:FS7) -> 0
FG8: SOY4 | FH8: ='Вторник 1'!FH8 -> 0 | FI8: ='Среда 2'!FI8 -> 0 | FJ8: ='Четверг 3'!FJ8 -> 0 | FK8: ='Пятница 4'!FK8 -> 0 | FL8: ='Суббота 5'!FL8 -> 0 | FM8: ='Воскресенье 6'!FM8 -> 0 | FN8: ='Понедельник 7'!FN8 -> 0 | FO8: ='Вторник 8'!FO8 -> 0 | FP8: ='Среда 9'!FP8 -> 0 | FQ8: ='Четверг 10'!FQ8 -> 0 | FR8: ='Пятница 11'!FR8 -> 0 | FS8: =SUMIF($FI$17:$FI$181,FG8,$FJ$17:$FJ$181) -> 0 | FT8: =SUM(FH8:FS8) -> 0
BN9: XS14 | CL9: XS21 | FG9: SOY5 | FH9: ='Вторник 1'!FH9 -> 0 | FI9: ='Среда 2'!FI9 -> 0 | FJ9: ='Четверг 3'!FJ9 -> 0 | FK9: ='Пятница 4'!FK9 -> 0 | FL9: ='Суббота 5'!FL9 -> 0 | FM9: ='Воскресенье 6'!FM9 -> 0 | FN9: ='Понедельник 7'!FN9 -> 0 | FO9: ='Вторник 8'!FO9 -> 0 | FP9: ='Среда 9'!FP9 -> 0 | FQ9: ='Четверг 10'!FQ9 -> 0 | FR9: ='Пятница 11'!FR9 -> 0 | FS9: =SUMIF($FI$17:$FI$181,FG9,$FJ$17:$FJ$181) -> 0 | FT9: =SUM(FH9:FS9) -> 0
Z10: XS02 | EA10: XS32 | FG10: SOY6 | FH10: ='Вторник 1'!FH10 -> 0 | FI10: ='Среда 2'!FI10 -> 0 | FJ10: ='Четверг 3'!FJ10 -> 0 | FK10: ='Пятница 4'!FK10 -> 0 | FL10: ='Суббота 5'!FL10 -> 0 | FM10: ='Воскресенье 6'!FM10 -> 0 | FN10: ='Понедельник 7'!FN10 -> 0 | FO10: ='Вторник 8'!FO10 -> 0 | FP10: ='Среда 9'!FP10 -> 0 | FQ10: ='Четверг 10'!FQ10 -> 0 | FR10: ='Пятница 11'!FR10 -> 0 | FS10: =SUMIF($FI$17:$FI$181,FG10,$FJ$17:$FJ$181) -> 0 | FT10: =SUM(FH10:FS10) -> 0
BN11: FREE | BZ11: S08 | CL11: FREE | FG11: SOY7 | FH11: ='Вторник 1'!FH11 -> 0 | FI11: ='Среда 2'!FI11 -> 0 | FJ11: ='Четверг 3'!FJ11 -> 0 | FK11: ='Пятница 4'!FK11 -> 0 | FL11: ='Суббота 5'!FL11 -> 0 | FM11: ='Воскресенье 6'!FM11 -> 0 | FN11: ='Понедельник 7'!FN11 -> 0 | FO11: ='Вторник 8'!FO11 -> 0 | FP11: ='Среда 9'!FP11 -> 0 | FQ11: ='Четверг 10'!FQ11 -> 0 | FR11: ='Пятница 11'!FR11 -> 0 | FS11: =SUMIF($FI$17:$FI$181,FG11,$FJ$17:$FJ$181) -> 0 | FT11: =SUM(FH11:FS11) -> 0
Z12: FREE | EA12: FREE | FG12: SOY8 | FH12: ='Вторник 1'!FH12 -> 0 | FI12: ='Среда 2'!FI12 -> 0 | FJ12: ='Четверг 3'!FJ12 -> 0 | FK12: ='Пятница 4'!FK12 -> 0 | FL12: ='Суббота 5'!FL12 -> 0 | FM12: ='Воскресенье 6'!FM12 -> 0 | FN12: ='Понедельник 7'!FN12 -> 0 | FO12: ='Вторник 8'!FO12 -> 0 | FP12: ='Среда 9'!FP12 -> 0 | FQ12: ='Четверг 10'!FQ12 -> 0 | FR12: ='Пятница 11'!FR12 -> 0 | FS12: =SUMIF($FI$17:$FI$181,FG12,$FJ$17:$FJ$181) -> 0 | FT12: =SUM(FH12:FS12) -> 0
BZ13: FREE | DI13: XS26 | FG13: FREE
AS14: XS07
DI15: FREE | FG15: Точка добычи | FI15: Cоюз | FJ15: Дают очков
AS16: FREE
FG17: ЛОГОВА | FH17: XS01 | FI17: =K27 -> FREE | FJ17: 80
S18: S01 | AI18: XS06 | EH18: S18 | FH18: XS02 | FI18: =Z12 -> FREE | FJ18: 80
DS19: XS31 | FH19: XS03 | FI19: =C52 -> FREE | FJ19: 80
S20: FREE | AI20: FREE | BN20: XS16 | CM20: XS20 | EH20: FREE | FH20: XS04 | FI20: =O44 -> FREE | FJ20: 80
DB21: XS25 | DS21: FREE | FH21: XS05 | FI21: =S36 -> FREE | FJ21: 80
AZ22: XS12 | BN22: FREE | CM22: FREE | FH22: XS06 | FI22: =AI20 -> FREE | FJ22: 80
DB23: FREE | FH23: XS07 | FI23: =AS16 -> FREE | FJ23: 80
AZ24: FREE | FH24: XS08 | FI24: =BB5 -> FREE | FJ24: 80
K25: XS01 | AQ25: XS11 | DK25: XS30 | FH25: XS09 | FI25: =V51 -> FREE | FJ25: 80
AA26: S02 | DZ26: S17 | EP26: XS38 | FH26: XS10 | FI26: =Z43 -> FREE | FJ26: 80
K27: FREE | AQ27: FREE | DK27: FREE | FH27: XS11 | FI27: =AQ27 -> FREE | FJ27: 80
AA28: FREE | BF28: M02 | BU28: S10 | CF28: S12 | CU28: M13 | DZ28: FREE | EP28: FREE | FH28: XS12 | FI28: =AZ24 -> FREE | FJ28: 80
FH29: XS13 | FI29: =J60 -> FREE | FJ29: 80
BF30: FREE | BU30: FREE | CF30: FREE | CU30: FREE | FH30: XS14 | FI30: =BN11 -> FREE | FJ30: 80
FH31: XS15 | FI31: =T67 -> FREE | FJ31: 80
FH32: XS16 | FI32: =BN22 -> FREE | FJ32: 80
AY33: S05 | DB33: S14 | EX33: SOY1 | FH33: XS17 | FI33: =C101 -> FREE | FJ33: 80
S34: XS05 | BL34: S02 | EH34: XS37 | FH34: XS18 | FI34: =J94 -> FREE | FJ34: 80
B35: SOY4 | AY35: FREE | CN35: S04 | DB35: FREE | FH35: XS19 | FI35: =T91 -> FREE | FJ35: 80
S36: FREE | BL36: FREE | BZ36: L03 | EH36: FREE | FH36: XS20 | FI36: =CM22 -> FREE | FJ36: 80
CN37: FREE | FH37: XS21 | FI37: =CL11 -> FREE | FJ37: 80
BZ38: FREE | FH38: XS22 | FI38: =CZ5 -> FREE | FJ38: 80
FH39: XS23 | FI39: =R112 -> FREE | FJ39: 80
BF40: M05 | BS40: M07 | CU40: M17 | FH40: XS24 | FI40: =X106 -> FREE | FJ40: 80
Z41: XS10 | AQ41: L01 | CH41: M12 | DJ41: L07 | EA41: XS36 | FH41: XS25 | FI41: =DB23 -> FREE | FJ41: 80
...
